<?xml version="1.0" ?>

<robot name="skidbot">
  <ros2_control name="RealRobot" type="system">
            <hardware>
                <plugin>diffdrive_arduino/DiffDriveArduino</plugin>
                <param name="left_wheel_name">left_wheel_joint</param>
                <param name="right_wheel_name">right_wheel_joint</param>
                <param name="loop_rate">30</param>
                <param name="device">/dev/ttyUSB0</param>
                <param name="baud_rate">57600</param>
                <param name="timeout">1000</param>
                <param name="enc_counts_per_rev">540</param>
            </hardware>
            <joint name="left_wheel_joint">
                <command_interface name="velocity">
                    <param name="min">-10</param>
                    <param name="max">10</param>
                </command_interface>
                <state_interface name="velocity"/>
                <state_interface name="position"/>
            </joint>
            <joint name="right_wheel_joint">
                <command_interface name="velocity">
                    <param name="min">-10</param>
                    <param name="max">10</param>
                </command_interface>
                <state_interface name="velocity"/>
                <state_interface name="position"/>
            </joint>
        </ros2_control>
        
 <!-- <ros2_control name="GazeboSystem" type="system">
        <hardware>
            <plugin>gazebo_ros2_control/GazeboSystem</plugin>
        </hardware>
        <joint name="left_wheel_joint">
            <command_interface name="velocity">
                <param name="min">-10</param>
                <param name="max">10</param>
            </command_interface>
            <state_interface name="velocity"/>
            <state_interface name="position"/>
        </joint>
        <joint name="right_wheel_joint">
            <command_interface name="velocity">
                <param name="min">-10</param>
                <param name="max">10</param>
            </command_interface>
            <state_interface name="velocity"/>
            <state_interface name="position"/>
        </joint>
    </ros2_control>
    -->
    <gazebo>
        <plugin name="gazebo_ros2_control" filename="libgazebo_ros2_control.so">
            <parameters>/home/ubuntu/gcamp_ros2_ws/src/gcamp_ros2_basic/gcamp_gazebo/config/controller.yaml</parameters>
        </plugin>
    </gazebo> 

  <link name="robot_footprint">
    <visual>
      <origin xyz="0 0 0" rpy="0 0 0" />
      <geometry>
        <box size="0.001 0.001 0.001" />
      </geometry>
    </visual>

    <collision>
      <origin xyz="0 0 0.017" rpy="0 0 0" />
      <geometry>
       <box size="0.001 0.001 0.001" />
      </geometry>
    </collision>
  </link>

  <link name="chassis">
    <inertial>
      <mass value="2" />
      <origin xyz="0 0 0.0" />
      <inertia ixx="0.01" ixy="0.0" ixz="0.0"
        iyy="0.01" iyz="0.0" izz="0.5" />
    </inertial>

    <visual>
      <origin xyz=" 0 0 0.1" rpy="0 0 0" />
      <geometry>
        <cylinder length="0.2" radius="0.16" />
      </geometry>
      <material name="blue">
        <color rgba="0 0 1 1"/>
      </material>
    </visual>

    <collision>
      <origin xyz="0.0 0.0 0.01" rpy="0 0 0" />
      <geometry>
        <cylinder length="0.03" radius="0.016495"/>
      </geometry>
    </collision>
  </link>

  <joint name="robot_footprint_joint" type="fixed">
    <origin xyz="0 0 0.017" rpy="0 0 0" />
    <parent link="robot_footprint"/>
    <child link="chassis" />
  </joint>

<link name="left_wheel">
    <inertial>
      <origin xyz="0 0 0"/>
      <mass value="0.01" />
      <inertia ixx="0.001" ixy="0.0" ixz="0.0"
        iyy="0.001" iyz="0.0" izz="0.001" />
    </inertial>

    <visual>
      <origin xyz="0 0 0" rpy="0 1.5707 1.5707" />
      <geometry>
        <cylinder radius="0.033" length = "0.023"/>
      </geometry>
    </visual>

    <collision>
      <origin xyz="0 0 0" rpy="0 1.5707 1.5707" />
      <geometry>
        <cylinder radius="0.033" length = "0.023"/>
      </geometry>
    </collision>
  </link>

  <joint name="left_wheel_joint" type="continuous">
    <origin xyz="0 0.18 0.015" rpy="0 0 0"/>
    <parent link="chassis"/>
    <child link="left_wheel"/>
    <axis xyz="0 1 0"/>
  </joint>

  <link name="right_wheel">
    <inertial>
      <origin xyz="0 0 0"/>
      <mass value="0.01" />
      <inertia ixx="0.001" ixy="0.0" ixz="0.0"
        iyy="0.001" iyz="0.0" izz="0.001" />
    </inertial>

    <visual>
      <origin xyz="0 0 0" rpy="0 1.5707 1.5707" />
      <geometry>
        <cylinder radius="0.033" length = "0.023"/>
      </geometry>
    </visual>

    <collision>
      <origin xyz="0 0 0" rpy="0 1.5707 1.5707" />
      <geometry>
        <cylinder radius="0.033" length = "0.023"/>
      </geometry>
    </collision>
  </link>

  <joint name="right_wheel_joint" type="continuous">
    <origin xyz="0 -0.18 0.015" rpy="0 0 0"/>
    <parent link="chassis"/>
    <child link="right_wheel"/>
    <axis xyz="0 1 0"/>
  </joint>
<link name="rear_wheel">
    <inertial>
      <origin xyz="0 0 0"/>
      <mass value="0.001" />
      <inertia ixx="0.0001" ixy="0.0" ixz="0.0"
        iyy="0.0001" iyz="0.0" izz="0.0001" />
    </inertial>

    <visual>
      <origin xyz="0 0 0" rpy="0 1.5707 1.5707"/>
      <geometry>
        <sphere radius="0.02" />
      </geometry>
    </visual>

    <collision>
      <origin xyz="0 0 0" rpy="0 1.5707 1.5707" />
      <geometry>
        <sphere radius="0.015" />
      </geometry>
    </collision>
  </link>
  <!-- fixed because there's no transmission -->
  <joint name="rear_castor_joint" type="fixed">
    <origin xyz="0.13 0 0.0" rpy="0 0 0"/>
    <parent link="chassis"/>
    <child link="rear_wheel"/>
    <axis xyz="0 1 0"/>
  </joint>  

  <gazebo reference="velodyne">
    <sensor name="lidar" type="ray">
      <always_on>true</always_on>
      <visualize>false</visualize>
      <update_rate>5</update_rate>
      <ray>
        <scan>
          <horizontal>
            <samples>360</samples>
            <resolution>1.000000</resolution>
            <min_angle>0.000000</min_angle>
            <max_angle>6.280000</max_angle>
          </horizontal>
        </scan>
        <range>
          <min>0.120000</min>
          <max>5</max>
          <resolution>0.015000</resolution>
        </range>
        <noise>
          <type>gaussian</type>
          <mean>0.0</mean>
          <stddev>0.01</stddev>
        </noise>
      </ray>
      <plugin name="scan" filename="libgazebo_ros_ray_sensor.so">
        <ros>
          <remapping>~/out:=scan</remapping>
        </ros>
        <output_type>sensor_msgs/LaserScan</output_type>
        <frame_name>velodyne</frame_name>
      </plugin>
    </sensor>
  </gazebo>

  <link name="velodyne">
    <inertial>
      <origin xyz="0 0 0" rpy="0 0 0"/>
      <mass value="0.125"/>
      <inertia ixx="0.001"  ixy="0"  ixz="0" iyy="0.001" iyz="0" izz="0.001" />
    </inertial>

    <collision>
      <origin xyz="0 0 0" rpy="0 0 0"/>
      <geometry>
         <cylinder radius="0.0508" length="0.055"/>
      </geometry>
    </collision>

    <visual>
      <origin xyz="0 0 0" rpy="0 0 0"/>
      <geometry>
         <cylinder radius="0.0508" length="0.055"/>
      </geometry>
    </visual>
</link>
<joint name="velodyne_joint" type="fixed">
	<parent link="chassis"/>
	<child link="velodyne"/>
	<origin xyz="0 0 0.18" rpy="0 0 0"/>
</joint>

</robot>
